<mujoco model="bouncyball">
  <compiler angle="radian" coordinate="local" inertiafromgeom="true" meshdir="meshes/"/>
  <!--
   <size nciodim="0" nconmax="100" njmax="500" nstack="-1"/>
    <option	timestep="0.00125" gravity="0 0 0"/>
        <motor ctrlrange='-.4 .4' ctrllimited='true'/>
        	margin="0.0001" solref=".02 0.08" solimp=".6 .8 .01"/>
   -->
    <option	timestep="0.00125" iterations="50" solver="PGS" tolerance="1e-6" gravity="0 0 -9.81">
    </option>

    <default>
        <geom contype='1' conaffinity='1' condim='1' rgba='0.8 0.6 .4 1'
        margin="0.0" solref=".04 0.05" solimp=".8 .8 .1"/>
    </default>

    <custom>
        <numeric name="snsr_covar" size="29" data="
        1e+2
        1e-6
        1e+1
        1e+1
        1e-4
        1e-3
        1e-0

        1e-6
        1e-6

        1e-0
        1e-0
        1e-2 1e-0 1e-0 1e-0 
        1e-5

        1e-8

        1e-5
        1e-5
        1e-5
        1e-5
        1e-5
        1e-5
        1e-5
        1e-5
        1e-5
        1e-5
        1e-5
        1e-5
        "
        />
      <numeric name="covar_diag" size="4" data="
        1e+2
        1e+1 

        1e-2
        1e-2
        "
        />

    <!--
        -->
    </custom>

    <asset>
      <material name="boring" reflectance="0.00005" rgba="0.7 0.6 0.6 1" shininess="1" specular=".1"/>
    </asset>

    <worldbody>
      <geom material="boring" pos="0 0 -0.1" size=".5 .5 .5" type="plane"/>
      <body pos="0 0 0">
        <joint name="rootx" type="slide" axis="1 0 0" pos="0 0 0" limited="false" range="-1 1" />
        <joint name="rootz" type="slide" axis="0 0 1" pos="0 0 0" limited="false" range="-1 1" />
        <!--
        <joint name="rooty" type="slide" axis="0 1 0" pos="0 0 0" limited="false" range="-1 1" />

        <joint name="roota" type="hinge" axis="1 0 0" pos="0 0 0" limited="false" />
        <joint name="rootb" type="hinge" axis="0 1 0" pos="0 0 0" limited="false" />
        <joint name="rootc" type="hinge" axis="0 0 1" pos="0 0 0" limited="false" />
        <site name="force" pos="0 0 0" type="sphere" size="0.05" rgba="1 1 0 0.5" />
        -->
        <site name="imu" pos="0 0 0" type="box" size="0.0158 0.0158 0.004" rgba="1 0 0 1" />

        <geom name="ball" type="sphere" size="0.05" rgba="1 0 0 1"/>
      </body>
    </worldbody>

    <sensor>

      <!--
      <jointpos joint="rootx" />
      <jointpos joint="rootz" />

      <jointvel joint="rootx" />
      <jointvel joint="rootz" />


      <jointpos joint="rooty" />
      <jointvel joint="rooty" />

      <accelerometer name="accel" site="imu" />
      <gyro name="gyro"           site="imu" />
      <force  name="force"        site="imu" />
      -->
      <framepos name="mocap" objtype='site' objname="imu" />
    </sensor>

    <actuator>
      <!--
      <motor name='rt_movement' joint='rooty'/>
      -->
      <motor name='right_movement' joint='rootx'/>
      <motor name='rht_movement' joint='rootz'/>
    </actuator>

  </mujoco>
