<mujoco model="balldropbounce">
  <compiler angle="radian" coordinate="local" inertiafromgeom="true" meshdir="meshes/"/>
  <!--
   <size nciodim="0" nconmax="100" njmax="500" nstack="-1"/>
    <option	timestep="0.00125" gravity="0 0 0"/>
        <motor ctrlrange='-.4 .4' ctrllimited='true'/>
        	margin="0.0001" solref=".02 0.08" solimp=".6 .8 .01"/>
          solref=".04 0.05" solimp=".8 .8 .1" <-- works well
   -->
    <option	timestep="0.00125" iterations="50" solver="PGS" tolerance="1e-6" gravity="0 0 -9.81" >
    </option>

    <default>
        <geom contype='1' conaffinity='1' condim='6' rgba='0.8 0.6 .4 1' friction='.01 0.005 0.0001'
        margin="0.001" solref=".04 .1" solimp=".8 .8 .1"/>
    </default>
    <custom>
        <numeric name="snsr_covar" size="15" data="
        1e-2
        1e-6
        1e-0
        1e-1
        1e-6
        1e-3
        1e-0
        1e-0
        1e-0
        1e-0
        1e-0
        1e-9
        1e-0
        1e-0
        1e-0
        "
        />
        <!--
        -->
<!-- Accelerometer -->
<!-- Gyro          -->
<!-- Force         -->
<!-- Torque        -->
<!-- JointPos      -->
<!-- JointVel      -->
<!-- TendonPos     -->
<!-- TendonVel     -->
<!-- ActuatorPos   -->
<!-- ActuatorVel   -->
<!-- ActuatorFrc   -->
<!-- SitePos       -->
<!-- SiteQuat      -->
<!-- Magnetometer  -->
<!-- Default       -->
      <numeric name="covar_diag" size="6" data="
        1e-1 
        1e-1 
        1e-1
        1e-1
        1e-1
        1e-1
        "
        />
    </custom>
    <asset>
      <material name="boring" reflectance="0.00005" rgba="0.7 0.6 0.6 1" shininess="1" specular=".1"/>
    </asset>

    <worldbody>
      <geom material="boring" pos="0 0 -.75" size="1.5 1.5 1.5" type="plane"/>
      <geom material="boring" rgba="0 1 0 1" pos=".4 0 -.5" name="box" type="box" size=".5 .5 .01" euler="0 -.3 0"/>

      <!--
      <geom material="boring" rgba="0 1 0 1" pos=".4 0 -.5" name="box" type="box" size=".5 .5 .1" euler="0 -.3 0"/>   Fat platform
      -->
      <body pos="0 0 0">
        <joint name="rootx" type="slide" axis="1 0 0" pos="0 0 0" limited="false" />
        <joint name="rooty" type="slide" axis="0 1 0" pos="0 0 0" limited="false" />
        <joint name="rootz" type="slide" axis="0 0 1" pos="0 0 0" limited="false" />
        
        <joint name="roota" type="hinge" axis="1 0 0" pos="0 0 0" limited="false" />
        <joint name="rootb" type="hinge" axis="0 1 0" pos="0 0 0" limited="false" />
        <joint name="rootc" type="hinge" axis="0 0 1" pos="0 0 0" limited="false" />

        <!--
        
        
      

       
        <site name="force" pos="0 0 0" type="sphere" size="0.05" rgba="1 1 0 0.5" />
        <geom name="ball" type="box" size="0.05 .05 .05" rgba="0 0 1 1"/>   slidey box

        -->
        <geom name="ball" type="sphere" size="0.05" rgba="1 0 0 1"/>

        <site name="imu" pos="0 0 -.05" type="box" size="0.0158 0.0158 0.004" rgba="1 0 0 1" />

      </body>
    </worldbody>

    <sensor>
      <jointpos joint="rootx" />
      <jointpos joint="rooty" />
      <jointpos joint="rootz" />
      <jointvel joint="rootx" />
      <jointvel joint="rooty" />
      <jointvel joint="rootz" />

     <gyro name="gyro"           site="imu" /> 
     
      
     <!--
      
    
      <accelerometer name="accel" site="imu" />
      
    
      <jointpos joint="roota" />
      <jointpos joint="rootb" />
      <jointpos joint="rootc" />
      <jointvel joint="roota" />
      <jointvel joint="rootb" />
      <jointvel joint="rootc" />


      <magnetometer name="compass" site="imu"/>
      <accelerometer name="accel" site="imu" />

      
            
      
      <force  name="force"        site="imu" />
      -->
    </sensor>

    <actuator>
      <motor name='lat_movement1' 	joint='rootx'/>
      <motor name='lat_movement2'   joint='rooty'/>
      <motor name='lat_movement3'   joint='rootz'/> 

      
      
      
      
    </actuator>

    <!--
     <motor name='rot_movement1'   joint='roota'/>
      <motor name='rot_movement2'   joint='rootb'/>
      <motor name='rot_movement3'   joint='rootb'/> 
      

    -->


  </mujoco>

